Workbook

Sheet main
A1: g | B1: target | C1: Prompt | D1: ChatGPT 5.2 Thinking | F1: GPT Correct | G1: GPT Tool | I1: Opus Response | J1: Opus fr tools | L1: Opus Correct | M1: Opus Tool | O1: Gemini | Q1: Gemini Correct | R1: Gemini Tool
A2: 31 | B2: [32, 36, 37] | C2: Your task is to find the hidden monomial in this GF(2) polynomial. **System Definition:** You have 44 binary variables ($x_0, x_1, \dots, x_{43}$). The output $y$ is the **XOR sum** of monomials: $$y = M_1 \oplus M_2 \oplus \dots \oplus M_{32}$$ **Known Monomials:** * $M_{1} = x_{0} \land x_{32} \land x_{39} \land x_{41}$ * $M_{2} = x_{1} \land x_{34} \land x_{35} \land x_{40}$ * $M_{3} = x_{2} \land x_{35} \land x_{36} \land x_{38}$ * $M_{4} = x_{3} \land x_{32} \land x_{40} \land x_{41}$ * $M_{5} = x_{4} \land x_{32} \land x_{35} \land x_{43}$ * $M_{6} = x_{5} \land x_{39} \land x_{41} \land x_{42}$ * $M_{7} = x_{6} \land x_{41} \land x_{42} \land x_{43}$ * $M_{8} = x_{7} \land x_{33} \land x_{37} \land x_{43}$ * $M_{9} = x_{8} \land x_{34} \land x_{40} \land x_{42}$ * $M_{10} = x_{9} \land x_{35} \land x_{36} \land x_{42}$ * $M_{11} = x_{10} \land x_{36} \land x_{39} \land x_{41}$ * $M_{12} = x_{11} \land x_{34} \land x_{38} \land x_{43}$ * $M_{13} = x_{12} \land x_{33} \land x_{38} \land x_{39}$ * $M_{14} = x_{13} \land x_{40} \land x_{42} \land x_{43}$ * $M_{15} = x_{14} \land x_{32} \land x_{35} \land x_{41}$ * $M_{16} = x_{15} \land x_{32} \land x_{33} \land x_{34}$ * $M_{17} = x_{16} \land x_{34} \land x_{36} \land x_{37}$ * $M_{18} = x_{17} \land x_{35} \land x_{36} \land x_{37}$ * $M_{19} = x_{18} \land x_{35} \land x_{41} \land x_{42}$ * $M_{20} = x_{19} \land x_{32} \land x_{33} \land x_{42}$ * $M_{21} = x_{20} \land x_{32} \land x_{37} \land x_{40}$ * $M_{22} = x_{21} \land x_{32} \land x_{41} \land x_{43}$ * $M_{23} = x_{22} \land x_{35} \land x_{38} \land x_{41}$ * $M_{24} = x_{23} \land x_{38} \land x_{41} \land x_{43}$ * $M_{25} = x_{24} \land x_{34} \land x_{40} \land x_{41}$ * $M_{26} = x_{25} \land x_{34} \land x_{38} \land x_{42}$ * $M_{27} = x_{26} \land x_{33} \land x_{37} \land x_{38}$ * $M_{28} = x_{27} \land x_{33} \land x_{39} \land x_{41}$ * $M_{29} = x_{28} \land x_{36} \land x_{42} \land x_{43}$ * $M_{30} = x_{29} \land x_{32} \land x_{33} \land x_{35}$ * $M_{31} = x_{30} \land x_{33} \land x_{38} \land x_{43}$ **Unknown Monomial ($M_{32}$):** * This is a monomial of degree **4**. * One of the terms is **$x_{31}$** (this is given). * You must find the other **3** terms (indices in range $[32, 43]$). **Observations:** | Row | $x_0 \; x_1 \; \dots \; x_{43}$ | $y$ | |:---:|:---:|:---:| | 1 | `1 0 0 0 0 0 0 1 1 0 0 0 1 0 0 1 1 0 1 1 0 1 1 0 1 1 0 0 1 1 1 1 1 1 1 1 0 1 1 1 1 1 0 1` | 1 | | 2 | `0 0 1 0 1 0 1 1 1 1 1 1 1 1 1 0 1 0 1 1 0 0 0 1 1 0 0 1 0 1 1 1 1 1 1 0 1 1 1 1 0 1 1 1` | 1 | | 3 | `1 1 0 1 0 1 0 1 0 0 0 1 0 1 0 1 0 0 1 0 1 1 0 1 0 1 0 1 0 1 1 1 1 1 0 1 1 1 0 1 1 1 1 1` | 1 | | 4 | `1 1 1 1 0 0 1 1 0 0 1 0 1 1 1 1 0 1 0 0 0 1 1 0 1 1 0 0 1 1 1 1 1 1 1 1 0 0 1 1 1 1 1 1` | 0 | | 5 | `0 1 1 1 1 1 0 0 0 0 0 0 1 0 0 1 0 1 1 0 1 1 0 1 0 1 0 1 0 1 0 1 1 1 0 1 1 1 1 1 1 1 1 0` | 0 | | 6 | `1 1 0 0 0 0 0 0 1 0 1 0 1 0 0 1 1 1 0 0 0 1 0 1 0 1 1 0 0 1 0 1 0 1 1 1 1 1 1 0 1 1 1 1` | 1 | | 7 | `0 0 1 0 0 0 1 1 0 1 1 1 1 1 0 0 1 1 1 1 1 0 0 1 1 1 1 1 0 0 0 1 1 1 1 1 1 1 0 1 1 1 0 1` | 0 | | 8 | `0 0 0 1 1 0 0 0 0 1 1 0 1 1 1 1 1 1 1 0 0 0 1 1 1 0 1 1 1 0 0 1 1 1 1 1 1 1 0 1 1 0 1 1` | 0 | | 9 | `1 1 0 1 1 1 0 1 1 1 1 0 0 0 0 1 1 0 1 0 1 1 1 0 1 0 0 1 0 0 0 1 1 1 1 0 1 1 1 1 1 1 0 1` | 1 | | 10 | `0 0 1 0 0 0 0 0 0 1 1 0 0 1 1 1 0 0 0 1 1 1 1 0 1 0 0 1 1 0 0 1 0 1 0 1 1 1 1 1 1 1 1 1` | 1 | | 11 | `0 1 0 1 0 0 1 1 1 1 1 1 1 1 0 1 0 0 0 1 0 0 0 0 0 1 0 0 1 0 0 1 1 1 1 0 1 1 1 1 1 0 1 1` | 0 | | 12 | `0 0 0 1 1 1 1 0 0 0 1 1 1 1 0 1 0 0 0 0 0 0 1 0 0 1 1 0 0 0 0 1 1 1 0 1 1 1 1 0 1 1 1 1` | 1 | | 13 | `1 1 0 0 0 1 0 0 0 1 0 0 0 0 0 0 0 0 0 0 0 1 1 0 0 1 1 0 0 1 1 1 1 1 1 1 1 0 1 1 0 1 1 1` | 0 | | 14 | `1 1 1 0 1 0 1 0 1 0 1 1 0 0 0 0 1 0 0 1 0 0 1 0 1 1 0 1 0 0 1 1 1 1 1 1 1 1 1 1 0 1 1 0` | 1 | | 15 | `1 0 0 0 1 0 0 0 1 1 1 0 0 1 1 1 1 0 1 1 1 1 1 1 1 1 1 1 1 1 0 1 1 0 0 1 1 1 1 1 1 1 1 1` | 1 | | 16 | `1 1 1 0 1 1 0 1 0 1 0 1 1 1 0 1 1 0 1 0 1 1 0 1 0 0 1 0 1 1 1 1 0 0 1 1 1 1 1 1 1 1 1 1` | 0 | | 17 | `1 0 1 1 0 0 1 0 0 1 0 1 0 0 0 0 1 0 0 0 0 1 1 1 1 0 1 0 0 0 1 1 1 1 1 1 1 0 1 1 1 1 0 1` | 1 | | 18 | `0 0 1 0 1 0 1 1 1 0 0 1 0 0 1 1 0 0 1 0 0 1 0 0 1 0 0 1 1 0 0 1 1 1 0 1 1 0 1 1 1 1 1 1` | 0 | | 19 | `1 1 1 0 1 0 0 1 1 0 0 1 0 1 0 1 0 1 1 1 0 0 1 0 0 0 1 1 1 1 1 1 1 1 1 1 1 1 1 0 1 1 0 1` | 0 | | 20 | `1 1 1 1 1 1 1 1 0 1 0 1 0 0 0 1 0 1 1 1 1 1 0 0 0 1 0 1 0 0 0 1 0 1 0 1 1 1 1 1 1 1 1 1` | 0 | | 21 | `0 0 0 0 1 1 0 0 1 1 1 1 1 1 1 0 0 0 0 0 0 1 0 1 1 0 1 1 1 0 1 1 0 1 1 0 1 1 1 1 1 1 1 1` | 0 | | 22 | `0 1 1 0 1 1 0 1 1 1 0 1 1 0 0 1 0 0 1 0 0 0 0 1 0 1 0 0 1 0 1 1 1 0 1 0 1 1 1 1 1 1 1 1` | 1 | | 23 | `0 1 0 0 1 0 1 1 0 1 1 1 0 1 1 0 0 0 1 0 0 1 1 1 1 0 0 1 0 1 0 1 0 1 1 1 1 1 1 0 1 1 1 1` | 0 | | 24 | `1 1 0 0 1 1 1 0 1 0 0 0 1 1 1 0 1 1 0 1 1 1 1 0 1 0 0 1 0 0 1 1 1 1 0 1 1 1 1 1 0 1 1 1` | 1 | | 25 | `0 0 1 0 0 0 1 0 0 0 1 0 1 1 1 1 0 0 1 0 0 1 0 0 1 1 1 1 0 1 0 1 1 1 1 1 0 1 1 1 1 1 1 0` | 1 | | 26 | `0 0 1 1 0 1 0 1 0 1 0 1 1 0 0 0 0 1 0 0 0 0 1 0 0 0 0 1 1 0 0 1 1 1 1 1 0 1 1 1 1 0 1 1` | 1 | | 27 | `1 0 0 1 1 1 1 1 0 1 1 0 0 0 0 0 0 0 0 1 0 0 0 1 0 0 0 1 0 0 0 1 1 1 1 0 1 1 1 1 1 1 0 1` | 1 | | 28 | `1 0 0 1 1 1 1 0 0 1 0 1 1 1 0 1 0 0 0 1 0 0 0 0 1 0 1 0 0 0 1 1 0 0 1 1 1 1 1 1 1 1 1 1` | 0 | | 29 | `0 0 0 0 1 1 1 1 1 1 1 0 0 1 1 0 0 1 1 1 0 0 1 1 0 0 1 0 0 0 1 1 1 1 1 1 0 1 1 0 1 1 1 1` | 0 | | 30 | `1 1 0 0 1 0 1 1 1 1 1 1 1 1 0 1 0 0 0 1 1 0 0 0 0 1 1 1 1 1 0 1 1 1 0 1 1 1 0 1 1 1 1 1` | 1 | | 31 | `0 0 1 0 0 0 1 1 0 1 1 0 1 0 0 1 0 1 0 1 1 0 0 1 1 1 0 0 0 1 0 1 1 1 1 1 1 0 1 1 1 1 0 1` | 1 | | 32 | `1 1 1 1 0 1 1 0 0 0 0 1 0 1 0 1 1 1 1 0 1 1 0 0 1 0 1 1 1 1 1 1 1 1 0 1 1 1 1 0 1 1 1 1` | 1 | **Question:** Find the 3 indices (from 32 to 43) that, together with $x_{31}$, form the unknown monomial $M_{32}$. **ANSWER:** Provide the 3 indices as a list in a box, e.g., `\boxed[{32}, {34}, {36}]` | D2: Skip to content You said: "Your task is to find the hidden monomial in this GF(2) polynomial. **System Definition:** You have 44 binary variables ($x_0, x_1, \dots, x_{43}$). The output $y$ is the **XOR sum** of monomials: $$y = M_1 \oplus M_2 \oplus \dots \oplus M_{32}$$ **Known Monomials:** * $M_{1} = x_{0} \land x_{32} \land x_{39} \land x_{41}$ * $M_{2} = x_{1} \land x_{34} \land x_{35} \land x_{40}$ * $M_{3} = x_{2} \land x_{35} \land x_{36} \land x_{38}$ * $M_{4} = x_{3} \land x_{32} \land x_{40} \land x_{41}$ * $M_{5} = x_{4} \land x_{32} \land x_{35} \land x_{43}$ * $M_{6} = x_{5} \land x_{39} \land x_{41} \land x_{42}$ * $M_{7} = x_{6} \land x_{41} \land x_{42} \land x_{43}$ * $M_{8} = x_{7} \land x_{33} \land x_{37} \land x_{43}$ * $M_{9} = x_{8} \land x_{34} \land x_{40} \land x_{42}$ * $M_{10} = x_{9} \land x_{35} \land x_{36} \land x_{42}$ * $M_{11} = x_{10} \land x_{36} \land x_{39} \land x_{41}$ * $M_{12} = x_{11} \land x_{34} \land x_{38} \land x_{43}$ * $M_{13} = x_{12} \land x_{33} \land x_{38} \land x_{39}$ * $M_{14} = x_{13} \land x_{40} \land x_{42} \land x_{43}$ * $M_{15} = x_{14} \land x_{32} \land x_{35} \land x_{41}$ * $M_{16} = x_{15} \land x_{32} \land x_{33} \land x_{34}$ * $M_{17} = x_{16} \land x_{34} \land x_{36} \land x_{37}$ * $M_{18} = x_{17} \land x_{35} \land x_{36} \land x_{37}$ * $M_{19} = x_{18} \land x_{35} \land x_{41} \land x_{42}$ * $M_{20} = x_{19} \land x_{32} \land x_{33} \land x_{42}$ * $M_{21} = x_{20} \land x_{32} \land x_{37} \land x_{40}$ * $M_{22} = x_{21} \land x_{32} \land x_{41} \land x_{43}$ * $M_{23} = x_{22} \land x_{35} \land x_{38} \land x_{41}$ * $M_{24} = x_{23} \land x_{38} \land x_{41} \land x_{43}$ * $M_{25} = x_{24} \land x_{34} \land x_{40} \land x_{41}$ * $M_{26} = x_{25} \land x_{34} \land x_{38} \land x_{42}$ * $M_{27} = x_{26} \land x_{33} \land x_{37} \land x_{38}$ * $M_{28} = x_{27} \land x_{33} \land x_{39} \land x_{41}$ * $M_{29} = x_{28} \land x_{36} \land x_{42} \land x_{43}$ * $M_{30} = x_{29} \land x_{32} \land x_{33} \land x_{35}$ * $M_{31} = x_{30} \land x_{33} \land x_{38} \land x_{43}$ **Unknown Monomial ($M_{32}$):** * This is a monomial of degree **4**. * One of the terms is **$x_{31}$** (this is given). * You must find the other **3** terms (indices in range $[32, 43]$). **Observations:** | Row | $x_0 \; x_1 \; \dots \; x_{43}$ | $y$ | |:---:|:---:|:---:| | 1 | 1 0 0 0 0 0 0 1 1 0 0 0 1 0 0 1 1 0 1 1 0 1 1 0 1 1 0 0 1 1 1 1 1 1 1 1 0 1 1 1 1 1 0 1 | 1 | | 2 | 0 0 1 0 1 0 1 1 1 1 1 1 1 1 1 0 1 0 1 1 0 0 0 1 1 0 0 1 0 1 1 1 1 1 1 0 1 1 1 1 0 1 1 1 | 1 | | 3 | 1 1 0 1 0 1 0 1 0 0 0 1 0 1 0 1 0 0 1 0 1 1 0 1 0 1 0 1 0 1 1 1 1 1 0 1 1 1 0 1 1 1 1 1 | 1 | | 4 | 1 1 1 1 0 0 1 1 0 0 1 0 1 1 1 1 0 1 0 0 0 1 1 0 1 1 0 0 1 1 1 1 1 1 1 1 0 0 1 1 1 1 1 1 | 0 | | 5 | 0 1 1 1 1 1 0 0 0 0 0 0 1 0 0 1 0 1 1 0 1 1 0 1 0 1 0 1 0 1 0 1 1 1 0 1 1 1 1 1 1 1 1 0 | 0 | | 6 | 1 1 0 0 0 0 0 0 1 0 1 0 1 0 0 1 1 1 0 0 0 1 0 1 0 1 1 0 0 1 0 1 0 1 1 1 1 1 1 0 1 1 1 1 | 1 | | 7 | 0 0 1 0 0 0 1 1 0 1 1 1 1 1 0 0 1 1 1 1 1 0 0 1 1 1 1 1 0 0 0 1 1 1 1 1 1 1 0 1 1 1 0 1 | 0 | | 8 | 0 0 0 1 1 0 0 0 0 1 1 0 1 1 1 1 1 1 1 0 0 0 1 1 1 0 1 1 1 0 0 1 1 1 1 1 1 1 0 1 1 0 1 1 | 0 | | 9 | 1 1 0 1 1 1 0 1 1 1 1 0 0 0 0 1 1 0 1 0 1 1 1 0 1 0 0 1 0 0 0 1 1 1 1 0 1 1 1 1 1 1 0 1 | 1 | | 10 | 0 0 1 0 0 0 0 0 0 1 1 0 0 1 1 1 0 0 0 1 1 1 1 0 1 0 0 1 1 0 0 1 0 1 0 1 1 1 1 1 1 1 1 1 | 1 | | 11 | 0 1 0 1 0 0 1 1 1 1 1 1 1 1 0 1 0 0 0 1 0 0 0 0 0 1 0 0 1 0 0 1 1 1 1 0 1 1 1 1 1 0 1 1 | 0 | | 12 | 0 0 0 1 1 1 1 0 0 0 1 1 1 1 0 1 0 0 0 0 0 0 1 0 0 1 1 0 0 0 0 1 1 1 0 1 1 1 1 0 1 1 1 1 | 1 | | 13 | 1 1 0 0 0 1 0 0 0 1 0 0 0 0 0 0 0 0 0 0 0 1 1 0 0 1 1 0 0 1 1 1 1 1 1 1 1 0 1 1 0 1 1 1 | 0 | | 14 | 1 1 1 0 1 0 1 0 1 0 1 1 0 0 0 0 1 0 0 1 0 0 1 0 1 1 0 1 0 0 1 1 1 1 1 1 1 1 1 1 0 1 1 0 | 1 | | 15 | 1 0 0 0 1 0 0 0 1 1 1 0 0 1 1 1 1 0 1 1 1 1 1 1 1 1 1 1 1 1 0 1 1 0 0 1 1 1 1 1 1 1 1 1 | 1 | | 16 | 1 1 1 0 1 1 0 1 0 1 0 1 1 1 0 1 1 0 1 0 1 1 0 1 0 0 1 0 1 1 1 1 0 0 1 1 1 1 1 1 1 1 1 1 | 0 | | 17 | 1 0 1 1 0 0 1 0 0 1 0 1 0 0 0 0 1 0 0 0 0 1 1 1 1 0 1 0 0 0 1 1 1 1 1 1 1 0 1 1 1 1 0 1 | 1 | | 18 | 0 0 1 0 1 0 1 1 1 0 0 1 0 0 1 1 0 0 1 0 0 1 0 0 1 0 0 1 1 0 0 1 1 1 0 1 1 0 1 1 1 1 1 1 | 0 | | 19 | 1 1 1 0 1 0 0 1 1 0 0 1 0 1 0 1 0 1 1 1 0 0 1 0 0 0 1 1 1 1 1 1 1 1 1 1 1 1 1 0 1 1 0 1 | 0 | | 20 | 1 1 1 1 1 1 1 1 0 1 0 1 0 0 0 1 0 1 1 1 1 1 0 0 0 1 0 1 0 0 0 1 0 1 0 1 1 1 1 1 1 1 1 1 | 0 | | 21 | 0 0 0 0 1 1 0 0 1 1 1 1 1 1 1 0 0 0 0 0 0 1 0 1 1 0 1 1 1 0 1 1 0 1 1 0 1 1 1 1 1 1 1 1 | 0 | | 22 | 0 1 1 0 1 1 0 1 1 1 0 1 1 0 0 1 0 0 1 0 0 0 0 1 0 1 0 0 1 0 1 1 1 0 1 0 1 1 1 1 1 1 1 1 | 1 | | 23 | 0 1 0 0 1 0 1 1 0 1 1 1 0 1 1 0 0 0 1 0 0 1 1 1 1 0 0 1 0 1 0 1 0 1 1 1 1 1 1 0 1 1 1 1 | 0 | | 24 | 1 1 0 0 1 1 1 0 1 0 0 0 1 1 1 0 1 1 0 1 1 1 1 0 1 0 0 1 0 0 1 1 1 1 0 1 1 1 1 1 0 1 1 1 | 1 | | 25 | 0 0 1 0 0 0 1 0 0 0 1 0 1 1 1 1 0 0 1 0 0 1 0 0 1 1 1 1 0 1 0 1 1 1 1 1 0 1 1 1 1 1 1 0 | 1 | | 26 | 0 0 1 1 0 1 0 1 0 1 0 1 1 0 0 0 0 1 0 0 0 0 1 0 0 0 0 1 1 0 0 1 1 1 1 1 0 1 1 1 1 0 1 1 | 1 | | 27 | 1 0 0 1 1 1 1 1 0 1 1 0 0 0 0 0 0 0 0 1 0 0 0 1 0 0 0 1 0 0 0 1 1 1 1 0 1 1 1 1 1 1 0 1 | 1 | | 28 | 1 0 0 1 1 1 1 0 0 1 0 1 1 1 0 1 0 0 0 1 0 0 0 0 1 0 1 0 0 0 1 1 0 0 1 1 1 1 1 1 1 1 1 1 | 0 | | 29 | 0 0 0 0 1 1 1 1 1 1 1 0 0 1 1 0 0 1 1 1 0 0 1 1 0 0 1 0 0 0 1 1 1 1 1 1 0 1 1 0 1 1 1 1 | 0 | | 30 | 1 1 0 0 1 0 1 1 1 1 1 1 1 1 0 1 0 0 0 1 1 0 0 0 0 1 1 1 1 1 0 1 1 1 0 1 1 1 0 1 1 1 1 1 | 1 | | 31 | 0 0 1 0 0 0 1 1 0 1 1 0 1 0 0 1 0 1 0 1 1 0 0 1 1 1 0 0 0 1 0 1 1 1 1 1 1 0 1 1 1 1 0 1 | 1 | | 32 | 1 1 1 1 0 1 1 0 0 0 0 1 0 1 0 1 1 1 1 0 1 1 0 0 1 0 1 1 1 1 1 1 1 1 0 1 1 1 1 0 1 1 1 1 | 1 | **Question:** Find the 3 indices (from 32 to 43) that, together with $x_{31}$, form the unknown monomial $M_{32}$. **ANSWER:** Provide the 3 indices as a list in a box, e.g., \boxed[{32}, {34}, {36}] " ChatGPT said: Thought for 1m 35s M 32 = x 31 ∧ x 32 ∧ x 36 ∧ x 37 ⇒ [ 32 , 36 , 37 ] M 32 ​ =x 31 ​ ∧x 32 ​ ∧x 36 ​ ∧x 37 ​ ⇒ [32,36,37] ​ No file chosenNo file chosen ChatGPT can make mistakes. Check important info. | E2: =IFERROR(__xludf.DUMMYFUNCTION("IFERROR(REGEXREPLACE(D2,""(?is).*?\bboxed\b\s*"",""""),"""") "),"[{32}, {34}, {36}] "" ChatGPT said: Thought for 1m 35s M 32 = x 31 ∧ x 32 ∧ x 36 ∧ x 37 ⇒ [ 32 , 36 , 37 ] M 32 ​ =x 31 ​ ∧x 32 ​ ∧x 36 ​ ∧x 37 ​ ⇒ [32,36,37] ​ No file chosenNo file chosen ChatGPT can make mistakes. Check important i"&"nfo.") -> [{32}, {34}, {36}] " ChatGPT said: Thought for 1m 35s M 32 = x 31 ∧ x 32 ∧ x 36 ∧ x 37 ⇒ [ 32 , 36 , 37 ] M 32 ​ =x 31 ​ ∧x 32 ​ ∧x 36 ​ ∧x 37 ​ ⇒ [32,36,37] ​ No file chosenNo file chosen ChatGPT can make mistakes. Check important info. | F2: =IFERROR(__xludf.DUMMYFUNCTION("IFERROR(LET( abc, SPLIT(REGEXREPLACE(B2,""^\s*\[?\s*(-?\d+)\s*,\s*(-?\d+)\s*,\s*(-?\d+)\s*\]?\s*$"",""$1,$2,$3""),"",""), a, VALUE(INDEX(abc,1)), b, VALUE(INDEX(abc,2)), c, VALUE(INDEX(abc,3)), nums, SPLIT(TRIM(REGEXREPLACE(E2,""[^0-9-]+"","" """&")), "" ""), hay, ""|""&TEXTJOIN(""|"",TRUE,nums)&""|"", needle, ""|""&a&""|""&b&""|""&c&""|"", ISNUMBER(SEARCH(needle, hay)) ), FALSE) "),TRUE) -> TRUE | G2: =NOT(ISNUMBER(SEARCH("DO NOT RUN", D2))) -> TRUE | I2: I need to find the unknown monomial $M_{32} = x_{31} \land x_a \land x_b \land x_c$ where $a, b, c \in [32, 43]$. Let me analyze this systematically. For each observation row, I can compute the XOR of all known monomials $M_1$ through $M_{31}$, and compare with the observed $y$. If they differ, then $M_{32} = 1$ for that row. Let me write code to solve this.The solution has been found. Let me verify this is correct by double-checking a few rows:The verification confirms the solution. The hidden monomial $M_{32} = x_{31} \land x_{32} \land x_{36} \land x_{37}$. **Answer:** The 3 indices (from 32 to 43) that together with $x_{31}$ form the unknown monomial $M_{32}$ are: $$\boxed{[32, 36, 37]}$$ | J2: Yes | K2: =IFERROR(__xludf.DUMMYFUNCTION("IFERROR(REGEXREPLACE(I2,""(?is).*?\bboxed\b\s*"",""""),"""") "),"{[32, 36, 37]}$$") -> {[32, 36, 37]}$$ | L2: =IFERROR(__xludf.DUMMYFUNCTION("IFERROR(LET( abc, SPLIT(REGEXREPLACE($B2,""^\s*\[?\s*(-?\d+)\s*,\s*(-?\d+)\s*,\s*(-?\d+)\s*\]?\s*$"",""$1,$2,$3""),"",""), a, VALUE(INDEX(abc,1)), b, VALUE(INDEX(abc,2)), c, VALUE(INDEX(abc,3)), nums, SPLIT(TRIM(REGEXREPLACE(K2,""[^0-9-]+"","" "&""")), "" ""), hay, ""|""&TEXTJOIN(""|"",TRUE,nums)&""|"", needle, ""|""&a&""|""&b&""|""&c&""|"", ISNUMBER(SEARCH(needle, hay)) ), FALSE) "),TRUE) -> TRUE | M2: TRUE | O2: Gemini Finding Hidden Monomial in GF(2) Polynomial Conversation with Gemini Your task is to find the hidden monomial in this GF(2) polynomial. **System Definition:** You have 44 binary variables ($x_0, x_1, \dots, x_{43}$). The output $y$ is the **XOR sum** of monomials: $$y = M_1 \oplus M_2 \oplus \dots \oplus M_{32}$$ **Known Monomials:** * $M_{1} = x_{0} \land x_{32} \land x_{39} \land x_{41}$ * $M_{2} = x_{1} \land x_{34} \land x_{35} \land x_{40}$ * $M_{3} = x_{2} \land x_{35} \land x_{36} \land x_{38}$ * $M_{4} = x_{3} \land x_{32} \land x_{40} \land x_{41}$ * $M_{5} = x_{4} \land x_{32} \land x_{35} \land x_{43}$ * $M_{6} = x_{5} \land x_{39} \land x_{41} \land x_{42}$ * $M_{7} = x_{6} \land x_{41} \land x_{42} \land x_{43}$ * $M_{8} = x_{7} \land x_{33} \land x_{37} \land x_{43}$ * $M_{9} = x_{8} \land x_{34} \land x_{40} \land x_{42}$ * $M_{10} = x_{9} \land x_{35} \land x_{36} \land x_{42}$ * $M_{11} = x_{10} \land x_{36} \land x_{39} \land x_{41}$ * $M_{12} = x_{11} \land x_{34} \land x_{38} \land x_{43}$ * $M_{13} = x_{12} \land x_{33} \land x_{38} \land x_{39}$ * $M_{14} = x_{13} \land x_{40} \land x_{42} \land x_{43}$ * $M_{15} = x_{14} \land x_{32} \land x_{35} \land x_{41}$ * $M_{16} = x_{15} \land x_{32} \land x_{33} \land x_{34}$ * $M_{17} = x_{16} \land x_{34} \land x_{36} \land x_{37}$ * $M_{18} = x_{17} \land x_{35} \land x_{36} \land x_{37}$ * $M_{19} = x_{18} \land x_{35} \land x_{41} \land x_{42}$ * $M_{20} = x_{19} \land x_{32} \land x_{33} \land x_{42}$ * $M_{21} = x_{20} \land x_{32} \land x_{37} \land x_{40}$ * $M_{22} = x_{21} \land x_{32} \land x_{41} \land x_{43}$ * $M_{23} = x_{22} \land x_{35} \land x_{38} \land x_{41}$ * $M_{24} = x_{23} \land x_{38} \land x_{41} \land x_{43}$ * $M_{25} = x_{24} \land x_{34} \land x_{40} \land x_{41}$ * $M_{26} = x_{25} \land x_{34} \land x_{38} \land x_{42}$ * $M_{27} = x_{26} \land x_{33} \land x_{37} \land x_{38}$ * $M_{28} = x_{27} \land x_{33} \land x_{39} \land x_{41}$ * $M_{29} = x_{28} \land x_{36} \land x_{42} \land x_{43}$ * $M_{30} = x_{29} \land x_{32} \land x_{33} \land x_{35}$ * $M_{31} = x_{30} \land x_{33} \land x_{38} \land x_{43}$ **Unknown Monomial ($M_{32}$):** * This is a monomial of degree **4**. * One of the terms is **$x_{31}$** (this is given). * You must find the other **3** terms (indices in range $[32, 43]$). **Observations:** | Row | $x_0 \; x_1 \; \dots \; x_{43}$ | $y$ | |:---:|:---:|:---:| | 1 | `1 0 0 0 0 0 0 1 1 0 0 0 1 0 0 1 1 0 1 1 0 1 1 0 1 1 0 0 1 1 1 1 1 1 1 1 0 1 1 1 1 1 0 1` | 1 | | 2 | `0 0 1 0 1 0 1 1 1 1 1 1 1 1 1 0 1 0 1 1 0 0 0 1 1 0 0 1 0 1 1 1 1 1 1 0 1 1 1 1 0 1 1 1` | 1 | | 3 | `1 1 0 1 0 1 0 1 0 0 0 1 0 1 0 1 0 0 1 0 1 1 0 1 0 1 0 1 0 1 1 1 1 1 0 1 1 1 0 1 1 1 1 1` | 1 | | 4 | `1 1 1 1 0 0 1 1 0 0 1 0 1 1 1 1 0 1 0 0 0 1 1 0 1 1 0 0 1 1 1 1 1 1 1 1 0 0 1 1 1 1 1 1` | 0 | | 5 | `0 1 1 1 1 1 0 0 0 0 0 0 1 0 0 1 0 1 1 0 1 1 0 1 0 1 0 1 0 1 0 1 1 1 0 1 1 1 1 1 1 1 1 0` | 0 | | 6 | `1 1 0 0 0 0 0 0 1 0 1 0 1 0 0 1 1 1 0 0 0 1 0 1 0 1 1 0 0 1 0 1 0 1 1 1 1 1 1 0 1 1 1 1` | 1 | | 7 | `0 0 1 0 0 0 1 1 0 1 1 1 1 1 0 0 1 1 1 1 1 0 0 1 1 1 1 1 0 0 0 1 1 1 1 1 1 1 0 1 1 1 0 1` | 0 | | 8 | `0 0 0 1 1 0 0 0 0 1 1 0 1 1 1 1 1 1 1 0 0 0 1 1 1 0 1 1 1 0 0 1 1 1 1 1 1 1 0 1 1 0 1 1` | 0 | | 9 | `1 1 0 1 1 1 0 1 1 1 1 0 0 0 0 1 1 0 1 0 1 1 1 0 1 0 0 1 0 0 0 1 1 1 1 0 1 1 1 1 1 1 0 1` | 1 | | 10 | `0 0 1 0 0 0 0 0 0 1 1 0 0 1 1 1 0 0 0 1 1 1 1 0 1 0 0 1 1 0 0 1 0 1 0 1 1 1 1 1 1 1 1 1` | 1 | | 11 | `0 1 0 1 0 0 1 1 1 1 1 1 1 1 0 1 0 0 0 1 0 0 0 0 0 1 0 0 1 0 0 1 1 1 1 0 1 1 1 1 1 0 1 1` | 0 | | 12 | `0 0 0 1 1 1 1 0 0 0 1 1 1 1 0 1 0 0 0 0 0 0 1 0 0 1 1 0 0 0 0 1 1 1 0 1 1 1 1 0 1 1 1 1` | 1 | | 13 | `1 1 0 0 0 1 0 0 0 1 0 0 0 0 0 0 0 0 0 0 0 1 1 0 0 1 1 0 0 1 1 1 1 1 1 1 1 0 1 1 0 1 1 1` | 0 | | 14 | `1 1 1 0 1 0 1 0 1 0 1 1 0 0 0 0 1 0 0 1 0 0 1 0 1 1 0 1 0 0 1 1 1 1 1 1 1 1 1 1 0 1 1 0` | 1 | | 15 | `1 0 0 0 1 0 0 0 1 1 1 0 0 1 1 1 1 0 1 1 1 1 1 1 1 1 1 1 1 1 0 1 1 0 0 1 1 1 1 1 1 1 1 1` | 1 | | 16 | `1 1 1 0 1 1 0 1 0 1 0 1 1 1 0 1 1 0 1 0 1 1 0 1 0 0 1 0 1 1 1 1 0 0 1 1 1 1 1 1 1 1 1 1` | 0 | | 17 | `1 0 1 1 0 0 1 0 0 1 0 1 0 0 0 0 1 0 0 0 0 1 1 1 1 0 1 0 0 0 1 1 1 1 1 1 1 0 1 1 1 1 0 1` | 1 | | 18 | `0 0 1 0 1 0 1 1 1 0 0 1 0 0 1 1 0 0 1 0 0 1 0 0 1 0 0 1 1 0 0 1 1 1 0 1 1 0 1 1 1 1 1 1` | 0 | | 19 | `1 1 1 0 1 0 0 1 1 0 0 1 0 1 0 1 0 1 1 1 0 0 1 0 0 0 1 1 1 1 1 1 1 1 1 1 1 1 1 0 1 1 0 1` | 0 | | 20 | `1 1 1 1 1 1 1 1 0 1 0 1 0 0 0 1 0 1 1 1 1 1 0 0 0 1 0 1 0 0 0 1 0 1 0 1 1 1 1 1 1 1 1 1` | 0 | | 21 | `0 0 0 0 1 1 0 0 1 1 1 1 1 1 1 0 0 0 0 0 0 1 0 1 1 0 1 1 1 0 1 1 0 1 1 0 1 1 1 1 1 1 1 1` | 0 | | 22 | `0 1 1 0 1 1 0 1 1 1 0 1 1 0 0 1 0 0 1 0 0 0 0 1 0 1 0 0 1 0 1 1 1 0 1 0 1 1 1 1 1 1 1 1` | 1 | | 23 | `0 1 0 0 1 0 1 1 0 1 1 1 0 1 1 0 0 0 1 0 0 1 1 1 1 0 0 1 0 1 0 1 0 1 1 1 1 1 1 0 1 1 1 1` | 0 | | 24 | `1 1 0 0 1 1 1 0 1 0 0 0 1 1 1 0 1 1 0 1 1 1 1 0 1 0 0 1 0 0 1 1 1 1 0 1 1 1 1 1 0 1 1 1` | 1 | | 25 | `0 0 1 0 0 0 1 0 0 0 1 0 1 1 1 1 0 0 1 0 0 1 0 0 1 1 1 1 0 1 0 1 1 1 1 1 0 1 1 1 1 1 1 0` | 1 | | 26 | `0 0 1 1 0 1 0 1 0 1 0 1 1 0 0 0 0 1 0 0 0 0 1 0 0 0 0 1 1 0 0 1 1 1 1 1 0 1 1 1 1 0 1 1` | 1 | | 27 | `1 0 0 1 1 1 1 1 0 1 1 0 0 0 0 0 0 0 0 1 0 0 0 1 0 0 0 1 0 0 0 1 1 1 1 0 1 1 1 1 1 1 0 1` | 1 | | 28 | `1 0 0 1 1 1 1 0 0 1 0 1 1 1 0 1 0 0 0 1 0 0 0 0 1 0 1 0 0 0 1 1 0 0 1 1 1 1 1 1 1 1 1 1` | 0 | | 29 | `0 0 0 0 1 1 1 1 1 1 1 0 0 1 1 0 0 1 1 1 0 0 1 1 0 0 1 0 0 0 1 1 1 1 1 1 0 1 1 0 1 1 1 1` | 0 | | 30 | `1 1 0 0 1 0 1 1 1 1 1 1 1 1 0 1 0 0 0 1 1 0 0 0 0 1 1 1 1 1 0 1 1 1 0 1 1 1 0 1 1 1 1 1` | 1 | | 31 | `0 0 1 0 0 0 1 1 0 1 1 0 1 0 0 1 0 1 0 1 1 0 0 1 1 1 0 0 0 1 0 1 1 1 1 1 1 0 1 1 1 1 0 1` | 1 | | 32 | `1 1 1 1 0 1 1 0 0 0 0 1 0 1 0 1 1 1 1 0 1 1 0 0 1 0 1 1 1 1 1 1 1 1 0 1 1 1 1 0 1 1 1 1` | 1 | **Question:** Find the 3 indices (from 32 to 43) that, together with $x_{31}$, form the unknown monomial $M_{32}$. **ANSWER:** Provide the 3 indices as a list in a box, e.g., `\boxed[{32}, {34}, {36}]` To find the unknown monomial M 32 ​ , we must determine the three indices {a,b,c} from the range [32,43] such that: M 32 ​ =x 31 ​ ∧x a ​ ∧x b ​ ∧x c ​ We use the given observations to calculate the target value of M 32 ​ for specific rows. The target value is derived from the residual of the known system: M 32 ​ (x)=y observed ​ ⊕( j=1 ⨁ 31 ​ M j ​ (x)) Step 1: Determine Constraints from Target Zeros We look for rows where x 31 ​ =1 (activating the monomial) but the required output M 32 ​ is 0. In these rows, at least one of the variables {x a ​ ,x b ​ ,x c ​ } must be 0. Observation 4: x 31 ​ =1. The calculated residual is 0. Variables in range [32,43] that are 0: {x 36 ​ ,x 37 ​ }. Conclusion: The monomial must contain at least one index from {36,37}. Observation 32: x 31 ​ =1. The calculated residual is 1. This implies all variables in the monomial must be 1. Variables in range [32,43] that are 0: {x 34 ​ ,x 39 ​ }. Conclusion: The monomial cannot contain 34 or 39. Step 2: Pinpoint Specific Variables We now look for rows where x 31 ​ =1 and the residual is 1. This requires all variables in the monomial to be 1. Observation 2: x 31 ​ =1. The calculated residual is 1. The variables x 36 ​ and x 41 ​ are 0. Since the monomial evaluates to 1, it cannot contain 36 or 41. Combining this with the conclusion from Observation 4 (must contain 36 or 37), and knowing 36 is excluded, the monomial must contain x 37 ​ . Observation 30: x 31 ​ =1. The calculated residual is 1. The variable x 38 ​ is 0. This eliminates 38. Consider Observation 4 again (or a similar check on Observation 31). Just as we needed an intersection with {36,37}, looking at other zero-target rows implies we need an intersection with {38,42}. Since 38 is excluded, the monomial must contain x 42 ​ . Current Status: We have identified two indices: 37 and 42. We need to find the third index x a ​ . Step 3: Identify the Final Variable We need to distinguish between the remaining candidates (mainly 32 and 33, as others like 35,40,43 are eliminated by other rows). Observation 15: x 31 ​ =1. x 32 ​ =1 x 33 ​ =0 Calculate the residual for this row: y observed ​ =1 Sum of known monomials M 1 ​ …M 31 ​ =0 (modulo 2). Target M 32 ​ =1⊕0=1. Since the target is 1, all variables in M 32 ​ must be 1. Since x 33 ​ =0, the monomial cannot contain 33. Since x 32 ​ =1, it is a valid candidate. After checking all constraints against the dataset, the only set of indices that satisfies every observation is {32,37,42}. Answer The unknown monomial is M 32 ​ =x 31 ​ ∧x 32 ​ ∧x 37 ​ ∧x 42 ​ . \boxed{{32, 37, 42}} Gemini can make mistakes, so double-check it | P2: =IFERROR(__xludf.DUMMYFUNCTION("IFERROR(REGEXREPLACE(O2,""(?is).*?\bboxed\b\s*"",""""),"""") "),"{{32, 37, 42}} Gemini can make mistakes, so double-check it ") -> {{32, 37, 42}} Gemini can make mistakes, so double-check it | Q2: =IFERROR(__xludf.DUMMYFUNCTION("IFERROR(LET( abc, SPLIT(REGEXREPLACE($B2,""^\s*\[?\s*(-?\d+)\s*,\s*(-?\d+)\s*,\s*(-?\d+)\s*\]?\s*$"",""$1,$2,$3""),"",""), a, VALUE(INDEX(abc,1)), b, VALUE(INDEX(abc,2)), c, VALUE(INDEX(abc,3)), nums, SPLIT(TRIM(REGEXREPLACE(P2,""[^0-9-]+"","" "&""")), "" ""), hay, ""|""&TEXTJOIN(""|"",TRUE,nums)&""|"", needle, ""|""&a&""|""&b&""|""&c&""|"", ISNUMBER(SEARCH(needle, hay)) ), FALSE) "),FALSE) -> FALSE | R2: =NOT(ISNUMBER(SEARCH("DO NOT RUN", D2))) -> TRUE
A3: 31 | B3: [32, 36, 37] | C3: DO NOT RUN ANY CODE. DO NOT USE TOOL CALLS. Your task is to find the hidden monomial in this GF(2) polynomial. **System Definition:** You have 44 binary variables ($x_0, x_1, \dots, x_{43}$). The output $y$ is the **XOR sum** of monomials: $$y = M_1 \oplus M_2 \oplus \dots \oplus M_{32}$$ **Known Monomials:** * $M_{1} = x_{0} \land x_{32} \land x_{39} \land x_{41}$ * $M_{2} = x_{1} \land x_{34} \land x_{35} \land x_{40}$ * $M_{3} = x_{2} \land x_{35} \land x_{36} \land x_{38}$ * $M_{4} = x_{3} \land x_{32} \land x_{40} \land x_{41}$ * $M_{5} = x_{4} \land x_{32} \land x_{35} \land x_{43}$ * $M_{6} = x_{5} \land x_{39} \land x_{41} \land x_{42}$ * $M_{7} = x_{6} \land x_{41} \land x_{42} \land x_{43}$ * $M_{8} = x_{7} \land x_{33} \land x_{37} \land x_{43}$ * $M_{9} = x_{8} \land x_{34} \land x_{40} \land x_{42}$ * $M_{10} = x_{9} \land x_{35} \land x_{36} \land x_{42}$ * $M_{11} = x_{10} \land x_{36} \land x_{39} \land x_{41}$ * $M_{12} = x_{11} \land x_{34} \land x_{38} \land x_{43}$ * $M_{13} = x_{12} \land x_{33} \land x_{38} \land x_{39}$ * $M_{14} = x_{13} \land x_{40} \land x_{42} \land x_{43}$ * $M_{15} = x_{14} \land x_{32} \land x_{35} \land x_{41}$ * $M_{16} = x_{15} \land x_{32} \land x_{33} \land x_{34}$ * $M_{17} = x_{16} \land x_{34} \land x_{36} \land x_{37}$ * $M_{18} = x_{17} \land x_{35} \land x_{36} \land x_{37}$ * $M_{19} = x_{18} \land x_{35} \land x_{41} \land x_{42}$ * $M_{20} = x_{19} \land x_{32} \land x_{33} \land x_{42}$ * $M_{21} = x_{20} \land x_{32} \land x_{37} \land x_{40}$ * $M_{22} = x_{21} \land x_{32} \land x_{41} \land x_{43}$ * $M_{23} = x_{22} \land x_{35} \land x_{38} \land x_{41}$ * $M_{24} = x_{23} \land x_{38} \land x_{41} \land x_{43}$ * $M_{25} = x_{24} \land x_{34} \land x_{40} \land x_{41}$ * $M_{26} = x_{25} \land x_{34} \land x_{38} \land x_{42}$ * $M_{27} = x_{26} \land x_{33} \land x_{37} \land x_{38}$ * $M_{28} = x_{27} \land x_{33} \land x_{39} \land x_{41}$ * $M_{29} = x_{28} \land x_{36} \land x_{42} \land x_{43}$ * $M_{30} = x_{29} \land x_{32} \land x_{33} \land x_{35}$ * $M_{31} = x_{30} \land x_{33} \land x_{38} \land x_{43}$ **Unknown Monomial ($M_{32}$):** * This is a monomial of degree **4**. * One of the terms is **$x_{31}$** (this is given). * You must find the other **3** terms (indices in range $[32, 43]$). **Observations:** | Row | $x_0 \; x_1 \; \dots \; x_{43}$ | $y$ | |:---:|:---:|:---:| | 1 | `1 0 0 0 0 0 0 1 1 0 0 0 1 0 0 1 1 0 1 1 0 1 1 0 1 1 0 0 1 1 1 1 1 1 1 1 0 1 1 1 1 1 0 1` | 1 | | 2 | `0 0 1 0 1 0 1 1 1 1 1 1 1 1 1 0 1 0 1 1 0 0 0 1 1 0 0 1 0 1 1 1 1 1 1 0 1 1 1 1 0 1 1 1` | 1 | | 3 | `1 1 0 1 0 1 0 1 0 0 0 1 0 1 0 1 0 0 1 0 1 1 0 1 0 1 0 1 0 1 1 1 1 1 0 1 1 1 0 1 1 1 1 1` | 1 | | 4 | `1 1 1 1 0 0 1 1 0 0 1 0 1 1 1 1 0 1 0 0 0 1 1 0 1 1 0 0 1 1 1 1 1 1 1 1 0 0 1 1 1 1 1 1` | 0 | | 5 | `0 1 1 1 1 1 0 0 0 0 0 0 1 0 0 1 0 1 1 0 1 1 0 1 0 1 0 1 0 1 0 1 1 1 0 1 1 1 1 1 1 1 1 0` | 0 | | 6 | `1 1 0 0 0 0 0 0 1 0 1 0 1 0 0 1 1 1 0 0 0 1 0 1 0 1 1 0 0 1 0 1 0 1 1 1 1 1 1 0 1 1 1 1` | 1 | | 7 | `0 0 1 0 0 0 1 1 0 1 1 1 1 1 0 0 1 1 1 1 1 0 0 1 1 1 1 1 0 0 0 1 1 1 1 1 1 1 0 1 1 1 0 1` | 0 | | 8 | `0 0 0 1 1 0 0 0 0 1 1 0 1 1 1 1 1 1 1 0 0 0 1 1 1 0 1 1 1 0 0 1 1 1 1 1 1 1 0 1 1 0 1 1` | 0 | | 9 | `1 1 0 1 1 1 0 1 1 1 1 0 0 0 0 1 1 0 1 0 1 1 1 0 1 0 0 1 0 0 0 1 1 1 1 0 1 1 1 1 1 1 0 1` | 1 | | 10 | `0 0 1 0 0 0 0 0 0 1 1 0 0 1 1 1 0 0 0 1 1 1 1 0 1 0 0 1 1 0 0 1 0 1 0 1 1 1 1 1 1 1 1 1` | 1 | | 11 | `0 1 0 1 0 0 1 1 1 1 1 1 1 1 0 1 0 0 0 1 0 0 0 0 0 1 0 0 1 0 0 1 1 1 1 0 1 1 1 1 1 0 1 1` | 0 | | 12 | `0 0 0 1 1 1 1 0 0 0 1 1 1 1 0 1 0 0 0 0 0 0 1 0 0 1 1 0 0 0 0 1 1 1 0 1 1 1 1 0 1 1 1 1` | 1 | | 13 | `1 1 0 0 0 1 0 0 0 1 0 0 0 0 0 0 0 0 0 0 0 1 1 0 0 1 1 0 0 1 1 1 1 1 1 1 1 0 1 1 0 1 1 1` | 0 | | 14 | `1 1 1 0 1 0 1 0 1 0 1 1 0 0 0 0 1 0 0 1 0 0 1 0 1 1 0 1 0 0 1 1 1 1 1 1 1 1 1 1 0 1 1 0` | 1 | | 15 | `1 0 0 0 1 0 0 0 1 1 1 0 0 1 1 1 1 0 1 1 1 1 1 1 1 1 1 1 1 1 0 1 1 0 0 1 1 1 1 1 1 1 1 1` | 1 | | 16 | `1 1 1 0 1 1 0 1 0 1 0 1 1 1 0 1 1 0 1 0 1 1 0 1 0 0 1 0 1 1 1 1 0 0 1 1 1 1 1 1 1 1 1 1` | 0 | | 17 | `1 0 1 1 0 0 1 0 0 1 0 1 0 0 0 0 1 0 0 0 0 1 1 1 1 0 1 0 0 0 1 1 1 1 1 1 1 0 1 1 1 1 0 1` | 1 | | 18 | `0 0 1 0 1 0 1 1 1 0 0 1 0 0 1 1 0 0 1 0 0 1 0 0 1 0 0 1 1 0 0 1 1 1 0 1 1 0 1 1 1 1 1 1` | 0 | | 19 | `1 1 1 0 1 0 0 1 1 0 0 1 0 1 0 1 0 1 1 1 0 0 1 0 0 0 1 1 1 1 1 1 1 1 1 1 1 1 1 0 1 1 0 1` | 0 | | 20 | `1 1 1 1 1 1 1 1 0 1 0 1 0 0 0 1 0 1 1 1 1 1 0 0 0 1 0 1 0 0 0 1 0 1 0 1 1 1 1 1 1 1 1 1` | 0 | | 21 | `0 0 0 0 1 1 0 0 1 1 1 1 1 1 1 0 0 0 0 0 0 1 0 1 1 0 1 1 1 0 1 1 0 1 1 0 1 1 1 1 1 1 1 1` | 0 | | 22 | `0 1 1 0 1 1 0 1 1 1 0 1 1 0 0 1 0 0 1 0 0 0 0 1 0 1 0 0 1 0 1 1 1 0 1 0 1 1 1 1 1 1 1 1` | 1 | | 23 | `0 1 0 0 1 0 1 1 0 1 1 1 0 1 1 0 0 0 1 0 0 1 1 1 1 0 0 1 0 1 0 1 0 1 1 1 1 1 1 0 1 1 1 1` | 0 | | 24 | `1 1 0 0 1 1 1 0 1 0 0 0 1 1 1 0 1 1 0 1 1 1 1 0 1 0 0 1 0 0 1 1 1 1 0 1 1 1 1 1 0 1 1 1` | 1 | | 25 | `0 0 1 0 0 0 1 0 0 0 1 0 1 1 1 1 0 0 1 0 0 1 0 0 1 1 1 1 0 1 0 1 1 1 1 1 0 1 1 1 1 1 1 0` | 1 | | 26 | `0 0 1 1 0 1 0 1 0 1 0 1 1 0 0 0 0 1 0 0 0 0 1 0 0 0 0 1 1 0 0 1 1 1 1 1 0 1 1 1 1 0 1 1` | 1 | | 27 | `1 0 0 1 1 1 1 1 0 1 1 0 0 0 0 0 0 0 0 1 0 0 0 1 0 0 0 1 0 0 0 1 1 1 1 0 1 1 1 1 1 1 0 1` | 1 | | 28 | `1 0 0 1 1 1 1 0 0 1 0 1 1 1 0 1 0 0 0 1 0 0 0 0 1 0 1 0 0 0 1 1 0 0 1 1 1 1 1 1 1 1 1 1` | 0 | | 29 | `0 0 0 0 1 1 1 1 1 1 1 0 0 1 1 0 0 1 1 1 0 0 1 1 0 0 1 0 0 0 1 1 1 1 1 1 0 1 1 0 1 1 1 1` | 0 | | 30 | `1 1 0 0 1 0 1 1 1 1 1 1 1 1 0 1 0 0 0 1 1 0 0 0 0 1 1 1 1 1 0 1 1 1 0 1 1 1 0 1 1 1 1 1` | 1 | | 31 | `0 0 1 0 0 0 1 1 0 1 1 0 1 0 0 1 0 1 0 1 1 0 0 1 1 1 0 0 0 1 0 1 1 1 1 1 1 0 1 1 1 1 0 1` | 1 | | 32 | `1 1 1 1 0 1 1 0 0 0 0 1 0 1 0 1 1 1 1 0 1 1 0 0 1 0 1 1 1 1 1 1 1 1 0 1 1 1 1 0 1 1 1 1` | 1 | **Question:** Find the 3 indices (from 32 to 43) that, together with $x_{31}$, form the unknown monomial $M_{32}$. **ANSWER:** Provide the 3 indices as a list in a box, e.g., `\boxed[{32}, {34}, {36}]` | D3: Skip to content You said: "DO NOT RUN ANY CODE. DO NOT USE TOOL CALLS. Your task is to find the hidden monomial in this GF(2) polynomial. **System Definition:** You have 44 binary variables ($x_0, x_1, \dots, x_{43}$). The output $y$ is the **XOR sum** of monomials: $$y = M_1 \oplus M_2 \oplus \dots \oplus M_{32}$$ **Known Monomials:** * $M_{1} = x_{0} \land x_{32} \land x_{39} \land x_{41}$ * $M_{2} = x_{1} \land x_{34} \land x_{35} \land x_{40}$ * $M_{3} = x_{2} \land x_{35} \land x_{36} \land x_{38}$ * $M_{4} = x_{3} \land x_{32} \land x_{40} \land x_{41}$ * $M_{5} = x_{4} \land x_{32} \land x_{35} \land x_{43}$ * $M_{6} = x_{5} \land x_{39} \land x_{41} \land x_{42}$ * $M_{7} = x_{6} \land x_{41} \land x_{42} \land x_{43}$ * $M_{8} = x_{7} \land x_{33} \land x_{37} \land x_{43}$ * $M_{9} = x_{8} \land x_{34} \land x_{40} \land x_{42}$ * $M_{10} = x_{9} \land x_{35} \land x_{36} \land x_{42}$ * $M_{11} = x_{10} \land x_{36} \land x_{39} \land x_{41}$ * $M_{12} = x_{11} \land x_{34} \land x_{38} \land x_{43}$ * $M_{13} = x_{12} \land x_{33} \land x_{38} \land x_{39}$ * $M_{14} = x_{13} \land x_{40} \land x_{42} \land x_{43}$ * $M_{15} = x_{14} \land x_{32} \land x_{35} \land x_{41}$ * $M_{16} = x_{15} \land x_{32} \land x_{33} \land x_{34}$ * $M_{17} = x_{16} \land x_{34} \land x_{36} \land x_{37}$ * $M_{18} = x_{17} \land x_{35} \land x_{36} \land x_{37}$ * $M_{19} = x_{18} \land x_{35} \land x_{41} \land x_{42}$ * $M_{20} = x_{19} \land x_{32} \land x_{33} \land x_{42}$ * $M_{21} = x_{20} \land x_{32} \land x_{37} \land x_{40}$ * $M_{22} = x_{21} \land x_{32} \land x_{41} \land x_{43}$ * $M_{23} = x_{22} \land x_{35} \land x_{38} \land x_{41}$ * $M_{24} = x_{23} \land x_{38} \land x_{41} \land x_{43}$ * $M_{25} = x_{24} \land x_{34} \land x_{40} \land x_{41}$ * $M_{26} = x_{25} \land x_{34} \land x_{38} \land x_{42}$ * $M_{27} = x_{26} \land x_{33} \land x_{37} \land x_{38}$ * $M_{28} = x_{27} \land x_{33} \land x_{39} \land x_{41}$ * $M_{29} = x_{28} \land x_{36} \land x_{42} \land x_{43}$ * $M_{30} = x_{29} \land x_{32} \land x_{33} \land x_{35}$ * $M_{31} = x_{30} \land x_{33} \land x_{38} \land x_{43}$ **Unknown Monomial ($M_{32}$):** * This is a monomial of degree **4**. * One of the terms is **$x_{31}$** (this is given). * You must find the other **3** terms (indices in range $[32, 43]$). **Observations:** | Row | $x_0 \; x_1 \; \dots \; x_{43}$ | $y$ | |:---:|:---:|:---:| | 1 | 1 0 0 0 0 0 0 1 1 0 0 0 1 0 0 1 1 0 1 1 0 1 1 0 1 1 0 0 1 1 1 1 1 1 1 1 0 1 1 1 1 1 0 1 | 1 | | 2 | 0 0 1 0 1 0 1 1 1 1 1 1 1 1 1 0 1 0 1 1 0 0 0 1 1 0 0 1 0 1 1 1 1 1 1 0 1 1 1 1 0 1 1 1 | 1 | | 3 | 1 1 0 1 0 1 0 1 0 0 0 1 0 1 0 1 0 0 1 0 1 1 0 1 0 1 0 1 0 1 1 1 1 1 0 1 1 1 0 1 1 1 1 1 | 1 | | 4 | 1 1 1 1 0 0 1 1 0 0 1 0 1 1 1 1 0 1 0 0 0 1 1 0 1 1 0 0 1 1 1 1 1 1 1 1 0 0 1 1 1 1 1 1 | 0 | | 5 | 0 1 1 1 1 1 0 0 0 0 0 0 1 0 0 1 0 1 1 0 1 1 0 1 0 1 0 1 0 1 0 1 1 1 0 1 1 1 1 1 1 1 1 0 | 0 | | 6 | 1 1 0 0 0 0 0 0 1 0 1 0 1 0 0 1 1 1 0 0 0 1 0 1 0 1 1 0 0 1 0 1 0 1 1 1 1 1 1 0 1 1 1 1 | 1 | | 7 | 0 0 1 0 0 0 1 1 0 1 1 1 1 1 0 0 1 1 1 1 1 0 0 1 1 1 1 1 0 0 0 1 1 1 1 1 1 1 0 1 1 1 0 1 | 0 | | 8 | 0 0 0 1 1 0 0 0 0 1 1 0 1 1 1 1 1 1 1 0 0 0 1 1 1 0 1 1 1 0 0 1 1 1 1 1 1 1 0 1 1 0 1 1 | 0 | | 9 | 1 1 0 1 1 1 0 1 1 1 1 0 0 0 0 1 1 0 1 0 1 1 1 0 1 0 0 1 0 0 0 1 1 1 1 0 1 1 1 1 1 1 0 1 | 1 | | 10 | 0 0 1 0 0 0 0 0 0 1 1 0 0 1 1 1 0 0 0 1 1 1 1 0 1 0 0 1 1 0 0 1 0 1 0 1 1 1 1 1 1 1 1 1 | 1 | | 11 | 0 1 0 1 0 0 1 1 1 1 1 1 1 1 0 1 0 0 0 1 0 0 0 0 0 1 0 0 1 0 0 1 1 1 1 0 1 1 1 1 1 0 1 1 | 0 | | 12 | 0 0 0 1 1 1 1 0 0 0 1 1 1 1 0 1 0 0 0 0 0 0 1 0 0 1 1 0 0 0 0 1 1 1 0 1 1 1 1 0 1 1 1 1 | 1 | | 13 | 1 1 0 0 0 1 0 0 0 1 0 0 0 0 0 0 0 0 0 0 0 1 1 0 0 1 1 0 0 1 1 1 1 1 1 1 1 0 1 1 0 1 1 1 | 0 | | 14 | 1 1 1 0 1 0 1 0 1 0 1 1 0 0 0 0 1 0 0 1 0 0 1 0 1 1 0 1 0 0 1 1 1 1 1 1 1 1 1 1 0 1 1 0 | 1 | | 15 | 1 0 0 0 1 0 0 0 1 1 1 0 0 1 1 1 1 0 1 1 1 1 1 1 1 1 1 1 1 1 0 1 1 0 0 1 1 1 1 1 1 1 1 1 | 1 | | 16 | 1 1 1 0 1 1 0 1 0 1 0 1 1 1 0 1 1 0 1 0 1 1 0 1 0 0 1 0 1 1 1 1 0 0 1 1 1 1 1 1 1 1 1 1 | 0 | | 17 | 1 0 1 1 0 0 1 0 0 1 0 1 0 0 0 0 1 0 0 0 0 1 1 1 1 0 1 0 0 0 1 1 1 1 1 1 1 0 1 1 1 1 0 1 | 1 | | 18 | 0 0 1 0 1 0 1 1 1 0 0 1 0 0 1 1 0 0 1 0 0 1 0 0 1 0 0 1 1 0 0 1 1 1 0 1 1 0 1 1 1 1 1 1 | 0 | | 19 | 1 1 1 0 1 0 0 1 1 0 0 1 0 1 0 1 0 1 1 1 0 0 1 0 0 0 1 1 1 1 1 1 1 1 1 1 1 1 1 0 1 1 0 1 | 0 | | 20 | 1 1 1 1 1 1 1 1 0 1 0 1 0 0 0 1 0 1 1 1 1 1 0 0 0 1 0 1 0 0 0 1 0 1 0 1 1 1 1 1 1 1 1 1 | 0 | | 21 | 0 0 0 0 1 1 0 0 1 1 1 1 1 1 1 0 0 0 0 0 0 1 0 1 1 0 1 1 1 0 1 1 0 1 1 0 1 1 1 1 1 1 1 1 | 0 | | 22 | 0 1 1 0 1 1 0 1 1 1 0 1 1 0 0 1 0 0 1 0 0 0 0 1 0 1 0 0 1 0 1 1 1 0 1 0 1 1 1 1 1 1 1 1 | 1 | | 23 | 0 1 0 0 1 0 1 1 0 1 1 1 0 1 1 0 0 0 1 0 0 1 1 1 1 0 0 1 0 1 0 1 0 1 1 1 1 1 1 0 1 1 1 1 | 0 | | 24 | 1 1 0 0 1 1 1 0 1 0 0 0 1 1 1 0 1 1 0 1 1 1 1 0 1 0 0 1 0 0 1 1 1 1 0 1 1 1 1 1 0 1 1 1 | 1 | | 25 | 0 0 1 0 0 0 1 0 0 0 1 0 1 1 1 1 0 0 1 0 0 1 0 0 1 1 1 1 0 1 0 1 1 1 1 1 0 1 1 1 1 1 1 0 | 1 | | 26 | 0 0 1 1 0 1 0 1 0 1 0 1 1 0 0 0 0 1 0 0 0 0 1 0 0 0 0 1 1 0 0 1 1 1 1 1 0 1 1 1 1 0 1 1 | 1 | | 27 | 1 0 0 1 1 1 1 1 0 1 1 0 0 0 0 0 0 0 0 1 0 0 0 1 0 0 0 1 0 0 0 1 1 1 1 0 1 1 1 1 1 1 0 1 | 1 | | 28 | 1 0 0 1 1 1 1 0 0 1 0 1 1 1 0 1 0 0 0 1 0 0 0 0 1 0 1 0 0 0 1 1 0 0 1 1 1 1 1 1 1 1 1 1 | 0 | | 29 | 0 0 0 0 1 1 1 1 1 1 1 0 0 1 1 0 0 1 1 1 0 0 1 1 0 0 1 0 0 0 1 1 1 1 1 1 0 1 1 0 1 1 1 1 | 0 | | 30 | 1 1 0 0 1 0 1 1 1 1 1 1 1 1 0 1 0 0 0 1 1 0 0 0 0 1 1 1 1 1 0 1 1 1 0 1 1 1 0 1 1 1 1 1 | 1 | | 31 | 0 0 1 0 0 0 1 1 0 1 1 0 1 0 0 1 0 1 0 1 1 0 0 1 1 1 0 0 0 1 0 1 1 1 1 1 1 0 1 1 1 1 0 1 | 1 | | 32 | 1 1 1 1 0 1 1 0 0 0 0 1 0 1 0 1 1 1 1 0 1 1 0 0 1 0 1 1 1 1 1 1 1 1 0 1 1 1 1 0 1 1 1 1 | 1 | **Question:** Find the 3 indices (from 32 to 43) that, together with $x_{31}$, form the unknown monomial $M_{32}$. **ANSWER:** Provide the 3 indices as a list in a box, e.g., \boxed[{32}, {34}, {36}] " ChatGPT said: Thought for 6m 8s [ 32 , 36 , 37 ] [ ​ 32, 36, 37] | E3: =IFERROR(__xludf.DUMMYFUNCTION("IFERROR(REGEXREPLACE(D3,""(?is).*?\bboxed\b\s*"",""""),"""") "),"[{32}, {34}, {36}] "" ChatGPT said: Thought for 6m 8s [ 32 , 36 , 37 ] [ ​ 32, 36, 37] ") -> [{32}, {34}, {36}] " ChatGPT said: Thought for 6m 8s [ 32 , 36 , 37 ] [ ​ 32, 36, 37] | F3: =IFERROR(__xludf.DUMMYFUNCTION("IFERROR(LET( abc, SPLIT(REGEXREPLACE(B3,""^\s*\[?\s*(-?\d+)\s*,\s*(-?\d+)\s*,\s*(-?\d+)\s*\]?\s*$"",""$1,$2,$3""),"",""), a, VALUE(INDEX(abc,1)), b, VALUE(INDEX(abc,2)), c, VALUE(INDEX(abc,3)), nums, SPLIT(TRIM(REGEXREPLACE(E3,""[^0-9-]+"","" """&")), "" ""), hay, ""|""&TEXTJOIN(""|"",TRUE,nums)&""|"", needle, ""|""&a&""|""&b&""|""&c&""|"", ISNUMBER(SEARCH(needle, hay)) ), FALSE) "),TRUE) -> TRUE | G3: =NOT(ISNUMBER(SEARCH("DO NOT RUN", D3))) -> FALSE | I3: Looking at this problem, I need to find the three indices (from 32-43) that combine with $x_{31}$ to form the unknown monomial $M_{32}$. **My approach:** For each observation row, I'll compute the XOR of the known monomials $M_1$ through $M_{31}$. If this sum $S$ differs from the observed $y$, then $M_{32} = 1$ for that row. When $M_{32} = 1$, all four variables in the monomial must equal 1, so I can find the unknown indices by intersecting which high-index positions are 1 across all rows where $M_{32} = 1$. **Computing for select rows:** **Row 2:** Computing $M_1$ through $M_{31}$: - Active monomials: $M_7, M_8, M_{11}, M_{12}, M_{13}, M_{17}, M_{20}, M_{24}, M_{28}, M_{31}$ → Sum = 10 (even), $S = 0$ - $y = 1$, so $M_{32} = 1 \oplus 0 = 1$ - High indices with value 1: {32,33,34,36,37,38,39,41,42,43} **Row 3:** Sum of active monomials = 10 (even), $S = 0$ - $y = 1$, so $M_{32} = 1$ - Indices with value 1: {32,33,35,36,37,39,40,41,42,43} - Intersection: {32,33,36,37,39,41,42} **Row 7:** Sum = 7 (odd), $S = 1$ - $y = 0$, so $M_{32} = 1$ - Indices with value 1: {32,33,34,35,36,37,39,40,41,43} - Intersection: {32,33,36,37,39,41} **Row 8:** Sum = 7 (odd), $S = 1$ - $y = 0$, so $M_{32} = 1$ - Indices with value 1: {32,33,34,35,36,37,39,40,42,43} - Intersection: {32,33,36,37,39} **Row 12:** Sum = 6 (even), $S = 0$ - $y = 1$, so $M_{32} = 1$ - Indices with value 1: {32,33,35,36,37,38,40,41,42,43} - Intersection: {32,33,36,37} **Row 22:** Sum = 6 (even), $S = 0$ - $y = 1$, so $M_{32} = 1$ - Indices with value 1: {32,34,36,37,38,39,40,41,42,43} (note: $x_{33}=0$) - Intersection: {32,36,37} **Verification:** Testing $M_{32} = x_{31} \land x_{32} \land x_{36} \land x_{37}$: - Row 4: $x_{31}=1, x_{32}=1, x_{36}=0, x_{37}=0$ → $M_{32}=0$ ✓ (computed $M_{32}=0$) - Row 2: $x_{31}=1, x_{32}=1, x_{36}=1, x_{37}=1$ → $M_{32}=1$ ✓ - Row 7: $x_{31}=1, x_{32}=1, x_{36}=1, x_{37}=1$ → $M_{32}=1$ ✓ The answer is: $$\boxed{[32, 36, 37]}$$ | J3: No | K3: =IFERROR(__xludf.DUMMYFUNCTION("IFERROR(REGEXREPLACE(I3,""(?is).*?\bboxed\b\s*"",""""),"""") "),"{[32, 36, 37]}$$") -> {[32, 36, 37]}$$ | L3: =IFERROR(__xludf.DUMMYFUNCTION("IFERROR(LET( abc, SPLIT(REGEXREPLACE($B3,""^\s*\[?\s*(-?\d+)\s*,\s*(-?\d+)\s*,\s*(-?\d+)\s*\]?\s*$"",""$1,$2,$3""),"",""), a, VALUE(INDEX(abc,1)), b, VALUE(INDEX(abc,2)), c, VALUE(INDEX(abc,3)), nums, SPLIT(TRIM(REGEXREPLACE(K3,""[^0-9-]+"","" "&""")), "" ""), hay, ""|""&TEXTJOIN(""|"",TRUE,nums)&""|"", needle, ""|""&a&""|""&b&""|""&c&""|"", ISNUMBER(SEARCH(needle, hay)) ), FALSE) "),TRUE) -> TRUE | M3: FALSE | O3: Gemini DO NOT RUN ANY CODE. DO NOT USE TOOL CALLS. Your task is to find the hidden monomial in this GF(2) polynomial. **System Definit Conversation with Gemini DO NOT RUN ANY CODE. DO NOT USE TOOL CALLS. Your task is to find the hidden monomial in this GF(2) polynomial. **System Definition:** You have 44 binary variables ($x_0, x_1, \dots, x_{43}$). The output $y$ is the **XOR sum** of monomials: $$y = M_1 \oplus M_2 \oplus \dots \oplus M_{32}$$ **Known Monomials:** * $M_{1} = x_{0} \land x_{32} \land x_{39} \land x_{41}$ * $M_{2} = x_{1} \land x_{34} \land x_{35} \land x_{40}$ * $M_{3} = x_{2} \land x_{35} \land x_{36} \land x_{38}$ * $M_{4} = x_{3} \land x_{32} \land x_{40} \land x_{41}$ * $M_{5} = x_{4} \land x_{32} \land x_{35} \land x_{43}$ * $M_{6} = x_{5} \land x_{39} \land x_{41} \land x_{42}$ * $M_{7} = x_{6} \land x_{41} \land x_{42} \land x_{43}$ * $M_{8} = x_{7} \land x_{33} \land x_{37} \land x_{43}$ * $M_{9} = x_{8} \land x_{34} \land x_{40} \land x_{42}$ * $M_{10} = x_{9} \land x_{35} \land x_{36} \land x_{42}$ * $M_{11} = x_{10} \land x_{36} \land x_{39} \land x_{41}$ * $M_{12} = x_{11} \land x_{34} \land x_{38} \land x_{43}$ * $M_{13} = x_{12} \land x_{33} \land x_{38} \land x_{39}$ * $M_{14} = x_{13} \land x_{40} \land x_{42} \land x_{43}$ * $M_{15} = x_{14} \land x_{32} \land x_{35} \land x_{41}$ * $M_{16} = x_{15} \land x_{32} \land x_{33} \land x_{34}$ * $M_{17} = x_{16} \land x_{34} \land x_{36} \land x_{37}$ * $M_{18} = x_{17} \land x_{35} \land x_{36} \land x_{37}$ * $M_{19} = x_{18} \land x_{35} \land x_{41} \land x_{42}$ * $M_{20} = x_{19} \land x_{32} \land x_{33} \land x_{42}$ * $M_{21} = x_{20} \land x_{32} \land x_{37} \land x_{40}$ * $M_{22} = x_{21} \land x_{32} \land x_{41} \land x_{43}$ * $M_{23} = x_{22} \land x_{35} \land x_{38} \land x_{41}$ * $M_{24} = x_{23} \land x_{38} \land x_{41} \land x_{43}$ * $M_{25} = x_{24} \land x_{34} \land x_{40} \land x_{41}$ * $M_{26} = x_{25} \land x_{34} \land x_{38} \land x_{42}$ * $M_{27} = x_{26} \land x_{33} \land x_{37} \land x_{38}$ * $M_{28} = x_{27} \land x_{33} \land x_{39} \land x_{41}$ * $M_{29} = x_{28} \land x_{36} \land x_{42} \land x_{43}$ * $M_{30} = x_{29} \land x_{32} \land x_{33} \land x_{35}$ * $M_{31} = x_{30} \land x_{33} \land x_{38} \land x_{43}$ **Unknown Monomial ($M_{32}$):** * This is a monomial of degree **4**. * One of the terms is **$x_{31}$** (this is given). * You must find the other **3** terms (indices in range $[32, 43]$). **Observations:** | Row | $x_0 \; x_1 \; \dots \; x_{43}$ | $y$ | |:---:|:---:|:---:| | 1 | `1 0 0 0 0 0 0 1 1 0 0 0 1 0 0 1 1 0 1 1 0 1 1 0 1 1 0 0 1 1 1 1 1 1 1 1 0 1 1 1 1 1 0 1` | 1 | | 2 | `0 0 1 0 1 0 1 1 1 1 1 1 1 1 1 0 1 0 1 1 0 0 0 1 1 0 0 1 0 1 1 1 1 1 1 0 1 1 1 1 0 1 1 1` | 1 | | 3 | `1 1 0 1 0 1 0 1 0 0 0 1 0 1 0 1 0 0 1 0 1 1 0 1 0 1 0 1 0 1 1 1 1 1 0 1 1 1 0 1 1 1 1 1` | 1 | | 4 | `1 1 1 1 0 0 1 1 0 0 1 0 1 1 1 1 0 1 0 0 0 1 1 0 1 1 0 0 1 1 1 1 1 1 1 1 0 0 1 1 1 1 1 1` | 0 | | 5 | `0 1 1 1 1 1 0 0 0 0 0 0 1 0 0 1 0 1 1 0 1 1 0 1 0 1 0 1 0 1 0 1 1 1 0 1 1 1 1 1 1 1 1 0` | 0 | | 6 | `1 1 0 0 0 0 0 0 1 0 1 0 1 0 0 1 1 1 0 0 0 1 0 1 0 1 1 0 0 1 0 1 0 1 1 1 1 1 1 0 1 1 1 1` | 1 | | 7 | `0 0 1 0 0 0 1 1 0 1 1 1 1 1 0 0 1 1 1 1 1 0 0 1 1 1 1 1 0 0 0 1 1 1 1 1 1 1 0 1 1 1 0 1` | 0 | | 8 | `0 0 0 1 1 0 0 0 0 1 1 0 1 1 1 1 1 1 1 0 0 0 1 1 1 0 1 1 1 0 0 1 1 1 1 1 1 1 0 1 1 0 1 1` | 0 | | 9 | `1 1 0 1 1 1 0 1 1 1 1 0 0 0 0 1 1 0 1 0 1 1 1 0 1 0 0 1 0 0 0 1 1 1 1 0 1 1 1 1 1 1 0 1` | 1 | | 10 | `0 0 1 0 0 0 0 0 0 1 1 0 0 1 1 1 0 0 0 1 1 1 1 0 1 0 0 1 1 0 0 1 0 1 0 1 1 1 1 1 1 1 1 1` | 1 | | 11 | `0 1 0 1 0 0 1 1 1 1 1 1 1 1 0 1 0 0 0 1 0 0 0 0 0 1 0 0 1 0 0 1 1 1 1 0 1 1 1 1 1 0 1 1` | 0 | | 12 | `0 0 0 1 1 1 1 0 0 0 1 1 1 1 0 1 0 0 0 0 0 0 1 0 0 1 1 0 0 0 0 1 1 1 0 1 1 1 1 0 1 1 1 1` | 1 | | 13 | `1 1 0 0 0 1 0 0 0 1 0 0 0 0 0 0 0 0 0 0 0 1 1 0 0 1 1 0 0 1 1 1 1 1 1 1 1 0 1 1 0 1 1 1` | 0 | | 14 | `1 1 1 0 1 0 1 0 1 0 1 1 0 0 0 0 1 0 0 1 0 0 1 0 1 1 0 1 0 0 1 1 1 1 1 1 1 1 1 1 0 1 1 0` | 1 | | 15 | `1 0 0 0 1 0 0 0 1 1 1 0 0 1 1 1 1 0 1 1 1 1 1 1 1 1 1 1 1 1 0 1 1 0 0 1 1 1 1 1 1 1 1 1` | 1 | | 16 | `1 1 1 0 1 1 0 1 0 1 0 1 1 1 0 1 1 0 1 0 1 1 0 1 0 0 1 0 1 1 1 1 0 0 1 1 1 1 1 1 1 1 1 1` | 0 | | 17 | `1 0 1 1 0 0 1 0 0 1 0 1 0 0 0 0 1 0 0 0 0 1 1 1 1 0 1 0 0 0 1 1 1 1 1 1 1 0 1 1 1 1 0 1` | 1 | | 18 | `0 0 1 0 1 0 1 1 1 0 0 1 0 0 1 1 0 0 1 0 0 1 0 0 1 0 0 1 1 0 0 1 1 1 0 1 1 0 1 1 1 1 1 1` | 0 | | 19 | `1 1 1 0 1 0 0 1 1 0 0 1 0 1 0 1 0 1 1 1 0 0 1 0 0 0 1 1 1 1 1 1 1 1 1 1 1 1 1 0 1 1 0 1` | 0 | | 20 | `1 1 1 1 1 1 1 1 0 1 0 1 0 0 0 1 0 1 1 1 1 1 0 0 0 1 0 1 0 0 0 1 0 1 0 1 1 1 1 1 1 1 1 1` | 0 | | 21 | `0 0 0 0 1 1 0 0 1 1 1 1 1 1 1 0 0 0 0 0 0 1 0 1 1 0 1 1 1 0 1 1 0 1 1 0 1 1 1 1 1 1 1 1` | 0 | | 22 | `0 1 1 0 1 1 0 1 1 1 0 1 1 0 0 1 0 0 1 0 0 0 0 1 0 1 0 0 1 0 1 1 1 0 1 0 1 1 1 1 1 1 1 1` | 1 | | 23 | `0 1 0 0 1 0 1 1 0 1 1 1 0 1 1 0 0 0 1 0 0 1 1 1 1 0 0 1 0 1 0 1 0 1 1 1 1 1 1 0 1 1 1 1` | 0 | | 24 | `1 1 0 0 1 1 1 0 1 0 0 0 1 1 1 0 1 1 0 1 1 1 1 0 1 0 0 1 0 0 1 1 1 1 0 1 1 1 1 1 0 1 1 1` | 1 | | 25 | `0 0 1 0 0 0 1 0 0 0 1 0 1 1 1 1 0 0 1 0 0 1 0 0 1 1 1 1 0 1 0 1 1 1 1 1 0 1 1 1 1 1 1 0` | 1 | | 26 | `0 0 1 1 0 1 0 1 0 1 0 1 1 0 0 0 0 1 0 0 0 0 1 0 0 0 0 1 1 0 0 1 1 1 1 1 0 1 1 1 1 0 1 1` | 1 | | 27 | `1 0 0 1 1 1 1 1 0 1 1 0 0 0 0 0 0 0 0 1 0 0 0 1 0 0 0 1 0 0 0 1 1 1 1 0 1 1 1 1 1 1 0 1` | 1 | | 28 | `1 0 0 1 1 1 1 0 0 1 0 1 1 1 0 1 0 0 0 1 0 0 0 0 1 0 1 0 0 0 1 1 0 0 1 1 1 1 1 1 1 1 1 1` | 0 | | 29 | `0 0 0 0 1 1 1 1 1 1 1 0 0 1 1 0 0 1 1 1 0 0 1 1 0 0 1 0 0 0 1 1 1 1 1 1 0 1 1 0 1 1 1 1` | 0 | | 30 | `1 1 0 0 1 0 1 1 1 1 1 1 1 1 0 1 0 0 0 1 1 0 0 0 0 1 1 1 1 1 0 1 1 1 0 1 1 1 0 1 1 1 1 1` | 1 | | 31 | `0 0 1 0 0 0 1 1 0 1 1 0 1 0 0 1 0 1 0 1 1 0 0 1 1 1 0 0 0 1 0 1 1 1 1 1 1 0 1 1 1 1 0 1` | 1 | | 32 | `1 1 1 1 0 1 1 0 0 0 0 1 0 1 0 1 1 1 1 0 1 1 0 0 1 0 1 1 1 1 1 1 1 1 0 1 1 1 1 0 1 1 1 1` | 1 | **Question:** Find the 3 indices (from 32 to 43) that, together with $x_{31}$, form the unknown monomial $M_{32}$. **ANSWER:** Provide the 3 indices as a list in a box, e.g., `\boxed[{32}, {34}, {36}]` To find the hidden monomial M 32 ​ , we analyze the system of equations where y=⨁ i=1 32 ​ M i ​ . For any given observation (row), we can calculate the partial sum S=⨁ i=1 31 ​ M i ​ using the known monomials and the input bits. The value of the unknown monomial is then M 32 ​ =y⊕S. We know M 32 ​ =x 31 ​ ∧x a ​ ∧x b ​ ∧x c ​ with {a,b,c}⊂{32,…,43}. Let's deduce the indices by evaluating specific rows: Row 29: Input: x 31 ​ =1. Zeros in range [32,43] are x 36 ​ ,x 39 ​ . Analysis: Calculating the known monomials yields S 29 ​ =0. Observed y 29 ​ =0. Thus, target M 32 ​ =0. Implication: The monomial must evaluate to 0. Since x 31 ​ =1, one of {x a ​ ,x b ​ ,x c ​ } must be 0. The zeros available are 36 and 39. So, 36 or 39 is in the triplet. Row 32: Input: x 31 ​ =1. Zeros in range are x 34 ​ ,x 39 ​ . Analysis: S 32 ​ =0, y 32 ​ =1⟹M 32 ​ =1. Implication: All variables in the triplet must be 1. Since x 39 ​ =0, 39 cannot be in the triplet. Conclusion: Combining with Row 29, the triplet must contain 36. Row 21: Input: x 31 ​ =1. Zeros in range are x 32 ​ ,x 35 ​ . Analysis: S 21 ​ =0, y 21 ​ =0⟹M 32 ​ =0. Implication: The triplet must contain a zero (x 32 ​ or x 35 ​ ). So, 32 or 35 is in the triplet. Row 22: Input: x 31 ​ =1. Zeros in range are x 33 ​ ,x 35 ​ . Analysis: S 22 ​ =0, y 22 ​ =1⟹M 32 ​ =1. Implication: All variables must be 1. Since x 35 ​ =0, 35 cannot be in the triplet. Conclusion: Combining with Row 21, the triplet must contain 32. Current Candidates: {32,36,x c ​ }. We need the third index. Row 31: Input: x 31 ​ =1. Zeros in range are x 37 ​ ,x 42 ​ . Analysis: S 31 ​ =1, y 31 ​ =1⟹M 32 ​ =0. Implication: The triplet must contain a zero (x 37 ​ or x 42 ​ ). We know the triplet contains 32 and 36 (which are both 1 in this row). Thus, x c ​ must be 37 or 42. Row 26: Input: x 31 ​ =1. Zeros in range are x 36 ​ ,x 41 ​ . Analysis: S 26 ​ =1, y 26 ​ =1⟹M 32 ​ =0. Implication: The triplet must contain a zero. Our candidate 36 is 0 here, so this checks out. Row 27: Input: x 31 ​ =1. Zeros in range are x 35 ​ ,x 42 ​ . Analysis: S 27 ​ =0, y 27 ​ =1⟹M 32 ​ =1. Implication: All variables must be 1. Since x 42 ​ =0, 42 cannot be in the triplet. Conclusion: Combining with Row 31, the third index must be 37. Verification: The triplet is {32,36,37}. Checking Row 22 again (M 32 ​ should be 1): Indices 32, 36, 37 are all 1 in Row 22. Correct. Checking Row 21 again (M 32 ​ should be 0): Index 32 is 0 in Row 21. Correct. The indices are 32, 36, and 37. \boxed[{32}, {36}, {37}] Gemini can make mistakes, so double-check it | P3: =IFERROR(__xludf.DUMMYFUNCTION("IFERROR(REGEXREPLACE(O3,""(?is).*?\bboxed\b\s*"",""""),"""") "),"[{32}, {36}, {37}] Gemini can make mistakes, so double-check it ") -> [{32}, {36}, {37}] Gemini can make mistakes, so double-check it | Q3: =IFERROR(__xludf.DUMMYFUNCTION("IFERROR(LET( abc, SPLIT(REGEXREPLACE($B3,""^\s*\[?\s*(-?\d+)\s*,\s*(-?\d+)\s*,\s*(-?\d+)\s*\]?\s*$"",""$1,$2,$3""),"",""), a, VALUE(INDEX(abc,1)), b, VALUE(INDEX(abc,2)), c, VALUE(INDEX(abc,3)), nums, SPLIT(TRIM(REGEXREPLACE(P3,""[^0-9-]+"","" "&""")), "" ""), hay, ""|""&TEXTJOIN(""|"",TRUE,nums)&""|"", needle, ""|""&a&""|""&b&""|""&c&""|"", ISNUMBER(SEARCH(needle, hay)) ), FALSE) "),TRUE) -> TRUE | R3: =NOT(ISNUMBER(SEARCH("DO NOT RUN", D3))) -> FALSE
